[2024-09-10T17:13:20.618+0000] {local_task_job_runner.py:123} INFO - ::group::Pre task execution logs
[2024-09-10T17:13:20.890+0000] {taskinstance.py:2612} INFO - Dependencies all met for dep_context=non-requeueable deps ti=<TaskInstance: detect_1fn_anomalies_dag.detect_1nf_and_insert_anomalies manual__2024-09-10T17:13:09.280715+00:00 [queued]>
[2024-09-10T17:13:20.919+0000] {taskinstance.py:2612} INFO - Dependencies all met for dep_context=requeueable deps ti=<TaskInstance: detect_1fn_anomalies_dag.detect_1nf_and_insert_anomalies manual__2024-09-10T17:13:09.280715+00:00 [queued]>
[2024-09-10T17:13:20.924+0000] {taskinstance.py:2865} INFO - Starting attempt 1 of 4
[2024-09-10T17:13:20.969+0000] {taskinstance.py:2888} INFO - Executing <Task(PythonOperator): detect_1nf_and_insert_anomalies> on 2024-09-10 17:13:09.280715+00:00
[2024-09-10T17:13:20.990+0000] {standard_task_runner.py:104} INFO - Running: ['airflow', 'tasks', 'run', 'detect_1fn_anomalies_dag', 'detect_1nf_and_insert_anomalies', 'manual__2024-09-10T17:13:09.280715+00:00', '--job-id', '2853', '--raw', '--subdir', 'DAGS_FOLDER/Dag_detect_1FN_anomaly.py', '--cfg-path', '/tmp/tmp6tq2pakt']
[2024-09-10T17:13:20.995+0000] {standard_task_runner.py:105} INFO - Job 2853: Subtask detect_1nf_and_insert_anomalies
[2024-09-10T17:13:20.995+0000] {logging_mixin.py:190} WARNING - /home/airflow/.local/lib/python3.12/site-packages/airflow/task/task_runner/standard_task_runner.py:70 DeprecationWarning: This process (pid=31228) is multi-threaded, use of fork() may lead to deadlocks in the child.
[2024-09-10T17:13:20.997+0000] {standard_task_runner.py:72} INFO - Started process 31262 to run task
[2024-09-10T17:13:21.805+0000] {task_command.py:467} INFO - Running <TaskInstance: detect_1fn_anomalies_dag.detect_1nf_and_insert_anomalies manual__2024-09-10T17:13:09.280715+00:00 [running]> on host 5f241b76205c
[2024-09-10T17:13:22.897+0000] {taskinstance.py:3131} INFO - Exporting env vars: AIRFLOW_CTX_DAG_OWNER='airflow' AIRFLOW_CTX_DAG_ID='detect_1fn_anomalies_dag' AIRFLOW_CTX_TASK_ID='detect_1nf_and_insert_anomalies' AIRFLOW_CTX_EXECUTION_DATE='2024-09-10T17:13:09.280715+00:00' AIRFLOW_CTX_TRY_NUMBER='1' AIRFLOW_CTX_DAG_RUN_ID='manual__2024-09-10T17:13:09.280715+00:00'
[2024-09-10T17:13:22.900+0000] {taskinstance.py:731} INFO - ::endgroup::
[2024-09-10T17:15:36.391+0000] {job.py:229} INFO - Heartbeat recovered after 11.23 seconds
[2024-09-10T17:21:19.968+0000] {job.py:229} INFO - Heartbeat recovered after 29.42 seconds
[2024-09-10T17:25:39.948+0000] {job.py:229} INFO - Heartbeat recovered after 21.86 seconds
[2024-09-10T17:30:19.456+0000] {logging_mixin.py:190} INFO - Une erreur s'est produite : (psycopg2.errors.IoError) could not open file "global/pg_filenode.map": Input/output error
CONTEXT:  parallel worker

[SQL: SELECT "anomalieDetected".id, "anomalieDetected"."Category", "anomalieDetected"."AnomalyType", "anomalieDetected"."Details", "anomalieDetected"."RelatedRecord" 
FROM "anomalieDetected" 
WHERE "anomalieDetected"."Category" = %(Category_1)s AND "anomalieDetected"."AnomalyType" = %(AnomalyType_1)s AND "anomalieDetected"."Details" = %(Details_1)s AND "anomalieDetected"."RelatedRecord" = %(RelatedRecord_1)s]
[parameters: {'Category_1': '1NF Violation', 'AnomalyType_1': 'Non-Atomic Values', 'Details_1': 'Column \'extra\' contains non-atomic values: {"host_name": "13d1dadf4f15", "full_command": "[\'/home/airflow/.local/bin/airflow\', \'scheduler\']"}.', 'RelatedRecord_1': 'Record 4569'}]
(Background on this error at: https://sqlalche.me/e/14/e3q8)
[2024-09-10T17:30:20.620+0000] {job.py:229} INFO - Heartbeat recovered after 17.19 seconds
[2024-09-10T17:30:20.738+0000] {taskinstance.py:3310} ERROR - Task failed with exception
Traceback (most recent call last):
  File "/home/airflow/.local/lib/python3.12/site-packages/sqlalchemy/engine/base.py", line 1910, in _execute_context
    self.dialect.do_execute(
  File "/home/airflow/.local/lib/python3.12/site-packages/sqlalchemy/engine/default.py", line 736, in do_execute
    cursor.execute(statement, parameters)
psycopg2.errors.IoError: could not open file "global/pg_filenode.map": Input/output error
CONTEXT:  parallel worker


The above exception was the direct cause of the following exception:

Traceback (most recent call last):
  File "/home/airflow/.local/lib/python3.12/site-packages/airflow/models/taskinstance.py", line 767, in _execute_task
    result = _execute_callable(context=context, **execute_callable_kwargs)
             ^^^^^^^^^^^^^^^^^^^^^^^^^^^^^^^^^^^^^^^^^^^^^^^^^^^^^^^^^^^^^
  File "/home/airflow/.local/lib/python3.12/site-packages/airflow/models/taskinstance.py", line 733, in _execute_callable
    return ExecutionCallableRunner(
           ^^^^^^^^^^^^^^^^^^^^^^^^
  File "/home/airflow/.local/lib/python3.12/site-packages/airflow/utils/operator_helpers.py", line 252, in run
    return self.func(*args, **kwargs)
           ^^^^^^^^^^^^^^^^^^^^^^^^^^
  File "/home/airflow/.local/lib/python3.12/site-packages/airflow/models/baseoperator.py", line 406, in wrapper
    return func(self, *args, **kwargs)
           ^^^^^^^^^^^^^^^^^^^^^^^^^^^
  File "/home/airflow/.local/lib/python3.12/site-packages/airflow/operators/python.py", line 238, in execute
    return_value = self.execute_callable()
                   ^^^^^^^^^^^^^^^^^^^^^^^
  File "/home/airflow/.local/lib/python3.12/site-packages/airflow/operators/python.py", line 256, in execute_callable
    return runner.run(*self.op_args, **self.op_kwargs)
           ^^^^^^^^^^^^^^^^^^^^^^^^^^^^^^^^^^^^^^^^^^^
  File "/home/airflow/.local/lib/python3.12/site-packages/airflow/utils/operator_helpers.py", line 252, in run
    return self.func(*args, **kwargs)
           ^^^^^^^^^^^^^^^^^^^^^^^^^^
  File "/opt/airflow/dags/Dag_detect_1FN_anomaly.py", line 93, in detect_and_insert_anomalies
    insert_anomalies(anomalies_df)
  File "/opt/airflow/dags/Dag_detect_1FN_anomaly.py", line 76, in insert_anomalies
    result = connection.execute(stmt_select).fetchone()
             ^^^^^^^^^^^^^^^^^^^^^^^^^^^^^^^
  File "/home/airflow/.local/lib/python3.12/site-packages/sqlalchemy/engine/base.py", line 1385, in execute
    return meth(self, multiparams, params, _EMPTY_EXECUTION_OPTS)
           ^^^^^^^^^^^^^^^^^^^^^^^^^^^^^^^^^^^^^^^^^^^^^^^^^^^^^^
  File "/home/airflow/.local/lib/python3.12/site-packages/sqlalchemy/sql/elements.py", line 334, in _execute_on_connection
    return connection._execute_clauseelement(
           ^^^^^^^^^^^^^^^^^^^^^^^^^^^^^^^^^^
  File "/home/airflow/.local/lib/python3.12/site-packages/sqlalchemy/engine/base.py", line 1577, in _execute_clauseelement
    ret = self._execute_context(
          ^^^^^^^^^^^^^^^^^^^^^^
  File "/home/airflow/.local/lib/python3.12/site-packages/sqlalchemy/engine/base.py", line 1953, in _execute_context
    self._handle_dbapi_exception(
  File "/home/airflow/.local/lib/python3.12/site-packages/sqlalchemy/engine/base.py", line 2134, in _handle_dbapi_exception
    util.raise_(
  File "/home/airflow/.local/lib/python3.12/site-packages/sqlalchemy/util/compat.py", line 211, in raise_
    raise exception
  File "/home/airflow/.local/lib/python3.12/site-packages/sqlalchemy/engine/base.py", line 1910, in _execute_context
    self.dialect.do_execute(
  File "/home/airflow/.local/lib/python3.12/site-packages/sqlalchemy/engine/default.py", line 736, in do_execute
    cursor.execute(statement, parameters)
sqlalchemy.exc.OperationalError: (psycopg2.errors.IoError) could not open file "global/pg_filenode.map": Input/output error
CONTEXT:  parallel worker

[SQL: SELECT "anomalieDetected".id, "anomalieDetected"."Category", "anomalieDetected"."AnomalyType", "anomalieDetected"."Details", "anomalieDetected"."RelatedRecord" 
FROM "anomalieDetected" 
WHERE "anomalieDetected"."Category" = %(Category_1)s AND "anomalieDetected"."AnomalyType" = %(AnomalyType_1)s AND "anomalieDetected"."Details" = %(Details_1)s AND "anomalieDetected"."RelatedRecord" = %(RelatedRecord_1)s]
[parameters: {'Category_1': '1NF Violation', 'AnomalyType_1': 'Non-Atomic Values', 'Details_1': 'Column \'extra\' contains non-atomic values: {"host_name": "13d1dadf4f15", "full_command": "[\'/home/airflow/.local/bin/airflow\', \'scheduler\']"}.', 'RelatedRecord_1': 'Record 4569'}]
(Background on this error at: https://sqlalche.me/e/14/e3q8)
[2024-09-10T17:30:26.287+0000] {taskinstance.py:1225} INFO - Marking task as UP_FOR_RETRY. dag_id=detect_1fn_anomalies_dag, task_id=detect_1nf_and_insert_anomalies, run_id=manual__2024-09-10T17:13:09.280715+00:00, execution_date=20240910T171309, start_date=20240910T171320, end_date=20240910T173026
[2024-09-10T17:30:32.082+0000] {job.py:229} INFO - Heartbeat recovered after 11.52 seconds
[2024-09-10T17:30:33.322+0000] {taskinstance.py:340} INFO - ::group::Post task execution logs
[2024-09-10T17:30:33.724+0000] {standard_task_runner.py:124} ERROR - Failed to execute job 2853 for task detect_1nf_and_insert_anomalies ((psycopg2.errors.IoError) could not open file "global/pg_filenode.map": Input/output error
CONTEXT:  parallel worker

[SQL: SELECT "anomalieDetected".id, "anomalieDetected"."Category", "anomalieDetected"."AnomalyType", "anomalieDetected"."Details", "anomalieDetected"."RelatedRecord" 
FROM "anomalieDetected" 
WHERE "anomalieDetected"."Category" = %(Category_1)s AND "anomalieDetected"."AnomalyType" = %(AnomalyType_1)s AND "anomalieDetected"."Details" = %(Details_1)s AND "anomalieDetected"."RelatedRecord" = %(RelatedRecord_1)s]
[parameters: {'Category_1': '1NF Violation', 'AnomalyType_1': 'Non-Atomic Values', 'Details_1': 'Column \'extra\' contains non-atomic values: {"host_name": "13d1dadf4f15", "full_command": "[\'/home/airflow/.local/bin/airflow\', \'scheduler\']"}.', 'RelatedRecord_1': 'Record 4569'}]
(Background on this error at: https://sqlalche.me/e/14/e3q8); 31262)
Traceback (most recent call last):
  File "/home/airflow/.local/lib/python3.12/site-packages/sqlalchemy/engine/base.py", line 1910, in _execute_context
    self.dialect.do_execute(
  File "/home/airflow/.local/lib/python3.12/site-packages/sqlalchemy/engine/default.py", line 736, in do_execute
    cursor.execute(statement, parameters)
psycopg2.errors.IoError: could not open file "global/pg_filenode.map": Input/output error
CONTEXT:  parallel worker


The above exception was the direct cause of the following exception:

Traceback (most recent call last):
  File "/home/airflow/.local/lib/python3.12/site-packages/airflow/task/task_runner/standard_task_runner.py", line 117, in _start_by_fork
    ret = args.func(args, dag=self.dag)
          ^^^^^^^^^^^^^^^^^^^^^^^^^^^^^
  File "/home/airflow/.local/lib/python3.12/site-packages/airflow/cli/cli_config.py", line 49, in command
    return func(*args, **kwargs)
           ^^^^^^^^^^^^^^^^^^^^^
  File "/home/airflow/.local/lib/python3.12/site-packages/airflow/utils/cli.py", line 115, in wrapper
    return f(*args, **kwargs)
           ^^^^^^^^^^^^^^^^^^
  File "/home/airflow/.local/lib/python3.12/site-packages/airflow/cli/commands/task_command.py", line 483, in task_run
    task_return_code = _run_task_by_selected_method(args, _dag, ti)
                       ^^^^^^^^^^^^^^^^^^^^^^^^^^^^^^^^^^^^^^^^^^^^
  File "/home/airflow/.local/lib/python3.12/site-packages/airflow/cli/commands/task_command.py", line 256, in _run_task_by_selected_method
    return _run_raw_task(args, ti)
           ^^^^^^^^^^^^^^^^^^^^^^^
  File "/home/airflow/.local/lib/python3.12/site-packages/airflow/cli/commands/task_command.py", line 341, in _run_raw_task
    return ti._run_raw_task(
           ^^^^^^^^^^^^^^^^^
  File "/home/airflow/.local/lib/python3.12/site-packages/airflow/utils/session.py", line 97, in wrapper
    return func(*args, session=session, **kwargs)
           ^^^^^^^^^^^^^^^^^^^^^^^^^^^^^^^^^^^^^^
  File "/home/airflow/.local/lib/python3.12/site-packages/airflow/models/taskinstance.py", line 3004, in _run_raw_task
    return _run_raw_task(
           ^^^^^^^^^^^^^^
  File "/home/airflow/.local/lib/python3.12/site-packages/airflow/models/taskinstance.py", line 273, in _run_raw_task
    TaskInstance._execute_task_with_callbacks(
  File "/home/airflow/.local/lib/python3.12/site-packages/airflow/models/taskinstance.py", line 3158, in _execute_task_with_callbacks
    result = self._execute_task(context, task_orig)
             ^^^^^^^^^^^^^^^^^^^^^^^^^^^^^^^^^^^^^^
  File "/home/airflow/.local/lib/python3.12/site-packages/airflow/models/taskinstance.py", line 3182, in _execute_task
    return _execute_task(self, context, task_orig)
           ^^^^^^^^^^^^^^^^^^^^^^^^^^^^^^^^^^^^^^^
  File "/home/airflow/.local/lib/python3.12/site-packages/airflow/models/taskinstance.py", line 767, in _execute_task
    result = _execute_callable(context=context, **execute_callable_kwargs)
             ^^^^^^^^^^^^^^^^^^^^^^^^^^^^^^^^^^^^^^^^^^^^^^^^^^^^^^^^^^^^^
  File "/home/airflow/.local/lib/python3.12/site-packages/airflow/models/taskinstance.py", line 733, in _execute_callable
    return ExecutionCallableRunner(
           ^^^^^^^^^^^^^^^^^^^^^^^^
  File "/home/airflow/.local/lib/python3.12/site-packages/airflow/utils/operator_helpers.py", line 252, in run
    return self.func(*args, **kwargs)
           ^^^^^^^^^^^^^^^^^^^^^^^^^^
  File "/home/airflow/.local/lib/python3.12/site-packages/airflow/models/baseoperator.py", line 406, in wrapper
    return func(self, *args, **kwargs)
           ^^^^^^^^^^^^^^^^^^^^^^^^^^^
  File "/home/airflow/.local/lib/python3.12/site-packages/airflow/operators/python.py", line 238, in execute
    return_value = self.execute_callable()
                   ^^^^^^^^^^^^^^^^^^^^^^^
  File "/home/airflow/.local/lib/python3.12/site-packages/airflow/operators/python.py", line 256, in execute_callable
    return runner.run(*self.op_args, **self.op_kwargs)
           ^^^^^^^^^^^^^^^^^^^^^^^^^^^^^^^^^^^^^^^^^^^
  File "/home/airflow/.local/lib/python3.12/site-packages/airflow/utils/operator_helpers.py", line 252, in run
    return self.func(*args, **kwargs)
           ^^^^^^^^^^^^^^^^^^^^^^^^^^
  File "/opt/airflow/dags/Dag_detect_1FN_anomaly.py", line 93, in detect_and_insert_anomalies
    insert_anomalies(anomalies_df)
  File "/opt/airflow/dags/Dag_detect_1FN_anomaly.py", line 76, in insert_anomalies
    result = connection.execute(stmt_select).fetchone()
             ^^^^^^^^^^^^^^^^^^^^^^^^^^^^^^^
  File "/home/airflow/.local/lib/python3.12/site-packages/sqlalchemy/engine/base.py", line 1385, in execute
    return meth(self, multiparams, params, _EMPTY_EXECUTION_OPTS)
           ^^^^^^^^^^^^^^^^^^^^^^^^^^^^^^^^^^^^^^^^^^^^^^^^^^^^^^
  File "/home/airflow/.local/lib/python3.12/site-packages/sqlalchemy/sql/elements.py", line 334, in _execute_on_connection
    return connection._execute_clauseelement(
           ^^^^^^^^^^^^^^^^^^^^^^^^^^^^^^^^^^
  File "/home/airflow/.local/lib/python3.12/site-packages/sqlalchemy/engine/base.py", line 1577, in _execute_clauseelement
    ret = self._execute_context(
          ^^^^^^^^^^^^^^^^^^^^^^
  File "/home/airflow/.local/lib/python3.12/site-packages/sqlalchemy/engine/base.py", line 1953, in _execute_context
    self._handle_dbapi_exception(
  File "/home/airflow/.local/lib/python3.12/site-packages/sqlalchemy/engine/base.py", line 2134, in _handle_dbapi_exception
    util.raise_(
  File "/home/airflow/.local/lib/python3.12/site-packages/sqlalchemy/util/compat.py", line 211, in raise_
    raise exception
  File "/home/airflow/.local/lib/python3.12/site-packages/sqlalchemy/engine/base.py", line 1910, in _execute_context
    self.dialect.do_execute(
  File "/home/airflow/.local/lib/python3.12/site-packages/sqlalchemy/engine/default.py", line 736, in do_execute
    cursor.execute(statement, parameters)
sqlalchemy.exc.OperationalError: (psycopg2.errors.IoError) could not open file "global/pg_filenode.map": Input/output error
CONTEXT:  parallel worker

[SQL: SELECT "anomalieDetected".id, "anomalieDetected"."Category", "anomalieDetected"."AnomalyType", "anomalieDetected"."Details", "anomalieDetected"."RelatedRecord" 
FROM "anomalieDetected" 
WHERE "anomalieDetected"."Category" = %(Category_1)s AND "anomalieDetected"."AnomalyType" = %(AnomalyType_1)s AND "anomalieDetected"."Details" = %(Details_1)s AND "anomalieDetected"."RelatedRecord" = %(RelatedRecord_1)s]
[parameters: {'Category_1': '1NF Violation', 'AnomalyType_1': 'Non-Atomic Values', 'Details_1': 'Column \'extra\' contains non-atomic values: {"host_name": "13d1dadf4f15", "full_command": "[\'/home/airflow/.local/bin/airflow\', \'scheduler\']"}.', 'RelatedRecord_1': 'Record 4569'}]
(Background on this error at: https://sqlalche.me/e/14/e3q8)
[2024-09-10T17:30:39.326+0000] {local_task_job_runner.py:266} INFO - Task exited with return code 1
[2024-09-10T17:30:41.237+0000] {local_task_job_runner.py:245} INFO - ::endgroup::
[2024-09-10T17:30:43.271+0000] {standard_task_runner.py:217} INFO - Process not found (most likely exited), stop collecting metrics
