[2024-09-07T23:40:16.326+0000] {local_task_job_runner.py:123} INFO - ::group::Pre task execution logs
[2024-09-07T23:40:17.896+0000] {taskinstance.py:2612} INFO - Dependencies all met for dep_context=non-requeueable deps ti=<TaskInstance: correction_Dag_1FN.correct_1nf_violations scheduled__2024-09-07T23:35:00+00:00 [queued]>
[2024-09-07T23:40:18.346+0000] {taskinstance.py:2612} INFO - Dependencies all met for dep_context=requeueable deps ti=<TaskInstance: correction_Dag_1FN.correct_1nf_violations scheduled__2024-09-07T23:35:00+00:00 [queued]>
[2024-09-07T23:40:18.357+0000] {taskinstance.py:2865} INFO - Starting attempt 1 of 2
[2024-09-07T23:40:19.047+0000] {taskinstance.py:2888} INFO - Executing <Task(PythonOperator): correct_1nf_violations> on 2024-09-07 23:35:00+00:00
[2024-09-07T23:40:19.672+0000] {logging_mixin.py:190} WARNING - /home/airflow/.local/lib/python3.12/site-packages/airflow/task/task_runner/standard_task_runner.py:70 DeprecationWarning: This process (pid=6299) is multi-threaded, use of fork() may lead to deadlocks in the child.
[2024-09-07T23:40:19.543+0000] {standard_task_runner.py:104} INFO - Running: ['airflow', 'tasks', 'run', 'correction_Dag_1FN', 'correct_1nf_violations', 'scheduled__2024-09-07T23:35:00+00:00', '--job-id', '558', '--raw', '--subdir', 'DAGS_FOLDER/Correction_dag_1FN.py', '--cfg-path', '/tmp/tmpz5au5t8w']
[2024-09-07T23:40:19.769+0000] {standard_task_runner.py:72} INFO - Started process 6323 to run task
[2024-09-07T23:40:19.780+0000] {standard_task_runner.py:105} INFO - Job 558: Subtask correct_1nf_violations
[2024-09-07T23:40:28.580+0000] {task_command.py:467} INFO - Running <TaskInstance: correction_Dag_1FN.correct_1nf_violations scheduled__2024-09-07T23:35:00+00:00 [running]> on host 13d1dadf4f15
[2024-09-07T23:40:29.200+0000] {job.py:229} INFO - Heartbeat recovered after 19.56 seconds
[2024-09-07T23:40:40.962+0000] {taskinstance.py:3131} INFO - Exporting env vars: AIRFLOW_CTX_DAG_OWNER='airflow' AIRFLOW_CTX_DAG_ID='correction_Dag_1FN' AIRFLOW_CTX_TASK_ID='correct_1nf_violations' AIRFLOW_CTX_EXECUTION_DATE='2024-09-07T23:35:00+00:00' AIRFLOW_CTX_TRY_NUMBER='1' AIRFLOW_CTX_DAG_RUN_ID='scheduled__2024-09-07T23:35:00+00:00'
[2024-09-07T23:40:41.014+0000] {taskinstance.py:731} INFO - ::endgroup::
[2024-09-07T23:40:41.990+0000] {logging_mixin.py:190} INFO - Erreur lors de la correction des anomalies : column "product_ids" does not exist
LINE 2:         SELECT customer_id, product_ids, order_date, total_a...
                                    ^
HINT:  Perhaps you meant to reference the column "orders.product_id".
[2024-09-07T23:40:41.992+0000] {python.py:240} INFO - Done. Returned value was: None
[2024-09-07T23:40:43.242+0000] {taskinstance.py:340} INFO - ::group::Post task execution logs
[2024-09-07T23:40:43.245+0000] {taskinstance.py:352} INFO - Marking task as SUCCESS. dag_id=correction_Dag_1FN, task_id=correct_1nf_violations, run_id=scheduled__2024-09-07T23:35:00+00:00, execution_date=20240907T233500, start_date=20240907T234017, end_date=20240907T234043
[2024-09-07T23:40:45.683+0000] {standard_task_runner.py:217} INFO - Process not found (most likely exited), stop collecting metrics
[2024-09-07T23:40:45.721+0000] {local_task_job_runner.py:266} INFO - Task exited with return code 0
[2024-09-07T23:40:47.339+0000] {local_task_job_runner.py:245} INFO - ::endgroup::
